Workbook

Sheet Scores & Stats
B2: VAS | F2: TOM
B4: #VALUE! | C4: ULTIMATE CHAMPION TOTAL PTS | D4: =D6+D7 -> 231 | F4: #VALUE! | G4: ULTIMATE CHAMPION TOTAL PTS | H4: =H6+H7 -> 221
B6: #VALUE! | C6: PREDICTION LEAGUE TOTAL PTS | D6: =Predictions!S402 -> 195 | F6: #VALUE! | G6: PREDICTION LEAGUE TOTAL PTS | H6: =Predictions!T402 -> 198
B7: #VALUE! | C7: STAR MAN TOTAL PTS | D7: ='Star Man'!V52 -> 36 | F7: #VALUE! | G7: STAR MAN TOTAL PTS | H7: ='Star Man'!V55 -> 23
B9: #VALUE! | C9: TOTAL CORRECT SCORES | D9: =Predictions!D399 -> 23 | F9: #VALUE! | G9: TOTAL CORRECT SCORES | H9: =Predictions!E399 -> 24
B10: #VALUE! | C10: TOTAL CORRECT RESULTS | D10: =Predictions!F399 -> 149 | F10: #VALUE! | G10: TOTAL CORRECT RESULTS | H10: =Predictions!G399 -> 150
B11: #VALUE! | C11: TOTAL STAR MAN GOALS | D11: =SUM('Star Man'!D5:D42) -> 11 | F11: #VALUE! | G11: TOTAL STAR MAN GOALS | H11: =SUM('Star Man'!L5:L42) -> 7
B12: #VALUE! | C12: TOTAL STAR MAN ASSISTS | D12: =SUM('Star Man'!E5:E42) -> 6 | F12: #VALUE! | G12: TOTAL STAR MAN ASSISTS | H12: =SUM('Star Man'!M5:M42) -> 4
B13: #VALUE! | C13: TOTAL STAR MAN YELLOWS | D13: =SUM('Star Man'!F5:F42) -> 2 | F13: #VALUE! | G13: TOTAL STAR MAN YELLOWS | H13: =SUM('Star Man'!N5:N42) -> 2
B14: #VALUE! | C14: TOTAL STAR MAN REDS | D14: =SUM('Star Man'!G5:G42) -> 1 | F14: #VALUE! | G14: TOTAL STAR MAN REDS | H14: =SUM('Star Man'!O5:O42) -> 0

Sheet Predictions
B2: VAS PREDICTIONS | K2: TOM PREDICTIONS | T2: ACTUAL RESULTS | AC2: ABBY'S FUNSIES PREDICTIONS
B6: GW | C6: HOME TEAM | D6: SCORE PREDICTIONS | H6: AWAY TEAM | K6: GW | L6: HOME TEAM | M6: SCORE PREDICTIONS | Q6: AWAY TEAM | T6: GW | U6: HOME TEAM | V6: RESULTS | Z6: AWAY TEAM | AC6: GW | AD6: HOME TEAM | AE6: RESULTS | AI6: AWAY TEAM
B7: 1 | C7: Liverpool | D7: #VALUE! | E7: 3 | F7: 1 | G7: #VALUE! | H7: Bournemouth | K7: 1 | L7: Liverpool | M7: #VALUE! | N7: 3 | O7: 0 | P7: #VALUE! | Q7: Bournemouth | T7: 1 | U7: Liverpool | V7: #VALUE! | W7: 4 | X7: 2 | Y7: #VALUE! | Z7: Bournemouth | AC7: 1 | AD7: Liverpool | AE7: #VALUE! | AF7: 2 | AG7: 1 | AH7: #VALUE! | AI7: Bournemouth
B8: 1 | C8: Aston Villa | D8: #VALUE! | E8: 2 | F8: 1 | G8: #VALUE! | H8: Newcastle | K8: 1 | L8: Aston Villa | M8: #VALUE! | N8: 2 | O8: 1 | P8: #VALUE! | Q8: Newcastle | T8: 1 | U8: Aston Villa | V8: #VALUE! | W8: 0 | X8: 0 | Y8: #VALUE! | Z8: Newcastle | AC8: 1 | AD8: Aston Villa | AE8: #VALUE! | AF8: 0 | AG8: 1 | AH8: #VALUE! | AI8: Newcastle
B9: 1 | C9: Brighton | D9: #VALUE! | E9: 1 | F9: 1 | G9: #VALUE! | H9: Fulham | K9: 1 | L9: Brighton | M9: #VALUE! | N9: 2 | O9: 1 | P9: #VALUE! | Q9: Fulham | T9: 1 | U9: Brighton | V9: #VALUE! | W9: 1 | X9: 1 | Y9: #VALUE! | Z9: Fulham | AC9: 1 | AD9: Brighton | AE9: #VALUE! | AF9: 1 | AG9: 1 | AH9: #VALUE! | AI9: Fulham
B10: 1 | C10: Nottingham Forest | D10: #VALUE! | E10: 2 | F10: 1 | G10: #VALUE! | H10: Brentford | K10: 1 | L10: Nottingham Forest | M10: #VALUE! | N10: 1 | O10: 2 | P10: #VALUE! | Q10: Brentford | T10: 1 | U10: Nottingham Forest | V10: #VALUE! | W10: 3 | X10: 1 | Y10: #VALUE! | Z10: Brentford | AC10: 1 | AD10: Nottingham Forest | AE10: #VALUE! | AF10: 2 | AG10: 2 | AH10: #VALUE! | AI10: Brentford
B11: 1 | C11: Sunderland | D11: #VALUE! | E11: 1 | F11: 2 | G11: #VALUE! | H11: West Ham | K11: 1 | L11: Sunderland | M11: #VALUE! | N11: 0 | O11: 2 | P11: #VALUE! | Q11: West Ham | T11: 1 | U11: Sunderland | V11: #VALUE! | W11: 3 | X11: 0 | Y11: #VALUE! | Z11: West Ham | AC11: 1 | AD11: Sunderland | AE11: #VALUE! | AF11: 0 | AG11: 0 | AH11: #VALUE! | AI11: West Ham
B12: 1 | C12: Tottenham | D12: #VALUE! | E12: 2 | F12: 0 | G12: #VALUE! | H12: Burnley | K12: 1 | L12: Tottenham | M12: #VALUE! | N12: 3 | O12: 1 | P12: #VALUE! | Q12: Burnley | T12: 1 | U12: Tottenham | V12: #VALUE! | W12: 3 | X12: 0 | Y12: #VALUE! | Z12: Burnley | AC12: 1 | AD12: Tottenham | AE12: #VALUE! | AF12: 1 | AG12: 0 | AH12: #VALUE! | AI12: Burnley
B13: 1 | C13: Wolverhampton | D13: #VALUE! | E13: 0 | F13: 3 | G13: #VALUE! | H13: Manchester City | K13: 1 | L13: Wolverhampton | M13: #VALUE! | N13: 0 | O13: 3 | P13: #VALUE! | Q13: Manchester City | T13: 1 | U13: Wolverhampton | V13: #VALUE! | W13: 0 | X13: 4 | Y13: #VALUE! | Z13: Manchester City | AC13: 1 | AD13: Wolverhampton | AE13: #VALUE! | AF13: 3 | AG13: 2 | AH13: #VALUE! | AI13: Manchester City
B14: 1 | C14: Chelsea | D14: #VALUE! | E14: 4 | F14: 2 | G14: #VALUE! | H14: Crystal Palace | K14: 1 | L14: Chelsea | M14: #VALUE! | N14: 2 | O14: 1 | P14: #VALUE! | Q14: Crystal Palace | T14: 1 | U14: Chelsea | V14: #VALUE! | W14: 0 | X14: 0 | Y14: #VALUE! | Z14: Crystal Palace | AC14: 1 | AD14: Chelsea | AE14: #VALUE! | AF14: 2 | AG14: 1 | AH14: #VALUE! | AI14: Crystal Palace
B15: 1 | C15: Manchester United | D15: #VALUE! | E15: 2 | F15: 2 | G15: #VALUE! | H15: Arsenal | K15: 1 | L15: Manchester United | M15: #VALUE! | N15: 1 | O15: 1 | P15: #VALUE! | Q15: Arsenal | T15: 1 | U15: Manchester United | V15: #VALUE! | W15: 0 | X15: 1 | Y15: #VALUE! | Z15: Arsenal | AC15: 1 | AD15: Manchester United | AE15: #VALUE! | AF15: 4 | AG15: 0 | AH15: #VALUE! | AI15: Arsenal
B16: 1 | C16: Leeds | D16: #VALUE! | E16: 1 | F16: 2 | G16: #VALUE! | H16: Everton | K16: 1 | L16: Leeds | M16: #VALUE! | N16: 0 | O16: 2 | P16: #VALUE! | Q16: Everton | T16: 1 | U16: Leeds | V16: #VALUE! | W16: 1 | X16: 0 | Y16: #VALUE! | Z16: Everton | AC16: 1 | AD16: Leeds | AE16: #VALUE! | AF16: 3 | AG16: 2 | AH16: #VALUE! | AI16: Everton
B17: 2 | C17: Bournemouth | D17: #VALUE! | E17: 2 | F17: 0 | G17: #VALUE! | H17: Wolverhampton | K17: 2 | L17: Bournemouth | M17: #VALUE! | N17: 2 | O17: 0 | P17: #VALUE! | Q17: Wolverhampton | T17: 2 | U17: Bournemouth | V17: #VALUE! | W17: 1 | X17: 0 | Y17: #VALUE! | Z17: Wolverhampton | AC17: 2 | AD17: Bournemouth | AE17: #VALUE! | AF17: 1 | AG17: 2 | AH17: #VALUE! | AI17: Wolverhampton
B18: 2 | C18: Arsenal | D18: #VALUE! | E18: 3 | F18: 0 | G18: #VALUE! | H18: Leeds | K18: 2 | L18: Arsenal | M18: #VALUE! | N18: 2 | O18: 1 | P18: #VALUE! | Q18: Leeds | T18: 2 | U18: Arsenal | V18: #VALUE! | W18: 5 | X18: 0 | Y18: #VALUE! | Z18: Leeds | AC18: 2 | AD18: Arsenal | AE18: #VALUE! | AF18: 2 | AG18: 3 | AH18: #VALUE! | AI18: Leeds
... B312: 31 | C312: Leeds | D312: #VALUE! | E312: 1 | F312: 2 | G312: #VALUE! | H312: Brentford | K312: 31 | L312: Leeds | M312: #VALUE! | N312: 1 | O312: 1 | P312: #VALUE! | Q312: Brentford | T312: 31 | U312: Leeds | V312: #VALUE! | W312: 0 | X312: 0 | Y312: #VALUE! | Z312: Brentford | AC312: 31 | AD312: Leeds | AE312: #VALUE! | AF312: 1 | AG312: 0 | AH312: #VALUE! | AI312: Brentford
B313: 31 | C313: Manchester City | D313: #VALUE! | E313: 3 | F313: 0 | G313: #VALUE! | H313: Crystal Palace | K313: 31 | L313: Manchester City | M313: #VALUE! | P313: #VALUE! | Q313: Crystal Palace | T313: 31 | U313: Manchester City | V313: #VALUE! | W313: 0 | X313: 1 | Y313: #VALUE! | Z313: Crystal Palace | AC313: 31 | AD313: Manchester City | AE313: #VALUE! | AH313: #VALUE! | AI313: Crystal Palace
B314: 31 | C314: Newcastle | D314: #VALUE! | E314: 1 | F314: 1 | G314: #VALUE! | H314: Sunderland | K314: 31 | L314: Newcastle | M314: #VALUE! | N314: 2 | O314: 1 | P314: #VALUE! | Q314: Sunderland | T314: 31 | U314: Newcastle | V314: #VALUE! | W314: 1 | X314: 2 | Y314: #VALUE! | Z314: Sunderland | AC314: 31 | AD314: Newcastle | AE314: #VALUE! | AF314: 2 | AG314: 1 | AH314: #VALUE! | AI314: Sunderland
B315: 31 | C315: Tottenham | D315: #VALUE! | E315: 2 | F315: 1 | G315: #VALUE! | H315: Nottingham Forest | K315: 31 | L315: Tottenham | M315: #VALUE! | N315: 2 | O315: 2 | P315: #VALUE! | Q315: Nottingham Forest | T315: 31 | U315: Tottenham | V315: #VALUE! | W315: 0 | X315: 3 | Y315: #VALUE! | Z315: Nottingham Forest | AC315: 31 | AD315: Tottenham | AE315: #VALUE! | AF315: 1 | AG315: 2 | AH315: #VALUE! | AI315: Nottingham Forest
B316: 31 | C316: Wolverhampton | D316: #VALUE! | E316: 0 | F316: 4 | G316: #VALUE! | H316: Arsenal | K316: 31 | L316: Wolverhampton | M316: #VALUE! | N316: 0 | O316: 3 | P316: #VALUE! | Q316: Arsenal | T316: 31 | U316: Wolverhampton | V316: #VALUE! | W316: 2 | X316: 2 | Y316: #VALUE! | Z316: Arsenal | AC316: 31 | AD316: Wolverhampton | AE316: #VALUE! | AF316: 0 | AG316: 2 | AH316: #VALUE! | AI316: Arsenal
B317: 32 | C317: Arsenal | D317: #VALUE! | E317: 2 | F317: 0 | G317: #VALUE! | H317: Bournemouth | K317: 32 | L317: Arsenal | M317: #VALUE! | N317: 3 | O317: 0 | P317: #VALUE! | Q317: Bournemouth | T317: 32 | U317: Arsenal | V317: #VALUE! | W317: 1 | X317: 2 | Y317: #VALUE! | Z317: Bournemouth | AC317: 32 | AD317: Arsenal | AE317: #VALUE! | AF317: 2 | AG317: 1 | AH317: #VALUE! | AI317: Bournemouth
B318: 32 | C318: Brentford | D318: #VALUE! | E318: 3 | F318: 1 | G318: #VALUE! | H318: Everton | K318: 32 | L318: Brentford | M318: #VALUE! | N318: 2 | O318: 2 | P318: #VALUE! | Q318: Everton | T318: 32 | U318: Brentford | V318: #VALUE! | W318: 2 | X318: 2 | Y318: #VALUE! | Z318: Everton | AC318: 32 | AD318: Brentford | AE318: #VALUE! | AF318: 1 | AG318: 1 | AH318: #VALUE! | AI318: Everton
B319: 32 | C319: Burnley | D319: #VALUE! | E319: 0 | F319: 1 | G319: #VALUE! | H319: Brighton | K319: 32 | L319: Burnley | M319: #VALUE! | N319: 0 | O319: 2 | P319: #VALUE! | Q319: Brighton | T319: 32 | U319: Burnley | V319: #VALUE! | W319: 0 | X319: 2 | Y319: #VALUE! | Z319: Brighton | AC319: 32 | AD319: Burnley | AE319: #VALUE! | AF319: 1 | AG319: 1 | AH319: #VALUE! | AI319: Brighton
B320: 32 | C320: Chelsea | D320: #VALUE! | E320: 0 | F320: 3 | G320: #VALUE! | H320: Manchester City | K320: 32 | L320: Chelsea | M320: #VALUE! | N320: 1 | O320: 1 | P320: #VALUE! | Q320: Manchester City | T320: 32 | U320: Chelsea | V320: #VALUE! | W320: 0 | X320: 3 | Y320: #VALUE! | Z320: Manchester City | AC320: 32 | AD320: Chelsea | AE320: #VALUE! | AF320: 2 | AG320: 2 | AH320: #VALUE! | AI320: Manchester City
B321: 32 | C321: Crystal Palace | D321: #VALUE! | E321: 2 | F321: 2 | G321: #VALUE! | H321: Newcastle | K321: 32 | L321: Crystal Palace | M321: #VALUE! | N321: 1 | O321: 1 | P321: #VALUE! | Q321: Newcastle | T321: 32 | U321: Crystal Palace | V321: #VALUE! | W321: 2 | X321: 1 | Y321: #VALUE! | Z321: Newcastle | AC321: 32 | AD321: Crystal Palace | AE321: #VALUE! | AF321: 0 | AG321: 2 | AH321: #VALUE! | AI321: Newcastle
B322: 32 | C322: Liverpool | D322: #VALUE! | E322: 2 | F322: 1 | G322: #VALUE! | H322: Fulham | K322: 32 | L322: Liverpool | M322: #VALUE! | N322: 2 | O322: 1 | P322: #VALUE! | Q322: Fulham | T322: 32 | U322: Liverpool | V322: #VALUE! | W322: 2 | X322: 0 | Y322: #VALUE! | Z322: Fulham | AC322: 32 | AD322: Liverpool | AE322: #VALUE! | AF322: 0 | AG322: 0 | AH322: #VALUE! | AI322: Fulham
B323: 32 | C323: Manchester United | D323: #VALUE! | E323: 3 | F323: 1 | G323: #VALUE! | H323: Leeds | K323: 32 | L323: Manchester United | M323: #VALUE! | N323: 2 | O323: 1 | P323: #VALUE! | Q323: Leeds | T323: 32 | U323: Manchester United | V323: #VALUE! | W323: 1 | X323: 2 | Y323: #VALUE! | Z323: Leeds | AC323: 32 | AD323: Manchester United | AE323: #VALUE! | AF323: 1 | AG323: 1 | AH323: #VALUE! | AI323: Leeds
B324: 32 | C324: Nottingham Forest | D324: #VALUE! | E324: 0 | F324: 2 | G324: #VALUE! | H324: Aston Villa | K324: 32 | L324: Nottingham Forest | M324: #VALUE! | N324: 1 | O324: 2 | P324: #VALUE! | Q324: Aston Villa | T324: 32 | U324: Nottingham Forest | V324: #VALUE! | W324: 1 | X324: 1 | Y324: #VALUE! | Z324: Aston Villa | AC324: 32 | AD324: Nottingham Forest | AE324: #VALUE! | AF324: 2 | AG324: 2 | AH324: #VALUE! | AI324: Aston Villa
B325: 32 | C325: Sunderland | D325: #VALUE! | E325: 2 | F325: 1 | G325: #VALUE! | H325: Tottenham | K325: 32 | L325: Sunderland | M325: #VALUE! | N325: 2 | O325: 0 | P325: #VALUE! | Q325: Tottenham | T325: 32 | U325: Sunderland | V325: #VALUE! | W325: 1 | X325: 0 | Y325: #VALUE! | Z325: Tottenham | AC325: 32 | AD325: Sunderland | AE325: #VALUE! | AF325: 2 | AG325: 1 | AH325: #VALUE! | AI325: Tottenham
... B356: 35 | C356: Wolverhampton | D356: #VALUE! | E356: 0 | F356: 2 | G356: #VALUE! | H356: Sunderland | K356: 35 | L356: Wolverhampton | M356: #VALUE! | N356: 2 | O356: 3 | P356: #VALUE! | Q356: Sunderland | T356: 35 | U356: Wolverhampton | V356: #VALUE! | W356: 1 | X356: 1 | Y356: #VALUE! | Z356: Sunderland | AC356: 35 | AD356: Wolverhampton | AE356: #VALUE! | AF356: 0 | AG356: 0 | AH356: #VALUE! | AI356: Sunderland
B357: 36 | C357: Brighton | D357: #VALUE! | E357: 3 | F357: 0 | G357: #VALUE! | H357: Wolverhampton | K357: 36 | L357: Brighton | M357: #VALUE! | P357: #VALUE! | Q357: Wolverhampton | T357: 36 | U357: Brighton | V357: #VALUE! | Y357: #VALUE! | Z357: Wolverhampton | AC357: 36 | AD357: Brighton | AE357: #VALUE! | AH357: #VALUE! | AI357: Wolverhampton
B358: 36 | C358: Burnley | D358: #VALUE! | E358: 1 | F358: 3 | G358: #VALUE! | H358: Aston Villa | K358: 36 | L358: Burnley | M358: #VALUE! | P358: #VALUE! | Q358: Aston Villa | T358: 36 | U358: Burnley | V358: #VALUE! | Y358: #VALUE! | Z358: Aston Villa | AC358: 36 | AD358: Burnley | AE358: #VALUE! | AH358: #VALUE! | AI358: Aston Villa
B359: 36 | C359: Crystal Palace | D359: #VALUE! | E359: 1 | F359: 2 | G359: #VALUE! | H359: Everton | K359: 36 | L359: Crystal Palace | M359: #VALUE! | P359: #VALUE! | Q359: Everton | T359: 36 | U359: Crystal Palace | V359: #VALUE! | Y359: #VALUE! | Z359: Everton | AC359: 36 | AD359: Crystal Palace | AE359: #VALUE! | AH359: #VALUE! | AI359: Everton
B360: 36 | C360: Fulham | D360: #VALUE! | E360: 1 | F360: 1 | G360: #VALUE! | H360: Bournemouth | K360: 36 | L360: Fulham | M360: #VALUE! | P360: #VALUE! | Q360: Bournemouth | T360: 36 | U360: Fulham | V360: #VALUE! | Y360: #VALUE! | Z360: Bournemouth | AC360: 36 | AD360: Fulham | AE360: #VALUE! | AH360: #VALUE! | AI360: Bournemouth
B361: 36 | C361: Liverpool | D361: #VALUE! | E361: 3 | F361: 1 | G361: #VALUE! | H361: Chelsea | K361: 36 | L361: Liverpool | M361: #VALUE! | P361: #VALUE! | Q361: Chelsea | T361: 36 | U361: Liverpool | V361: #VALUE! | Y361: #VALUE! | Z361: Chelsea | AC361: 36 | AD361: Liverpool | AE361: #VALUE! | AH361: #VALUE! | AI361: Chelsea
B362: 36 | C362: Manchester City | D362: #VALUE! | E362: 3 | F362: 1 | G362: #VALUE! | H362: Brentford | K362: 36 | L362: Manchester City | M362: #VALUE! | P362: #VALUE! | Q362: Brentford | T362: 36 | U362: Manchester City | V362: #VALUE! | Y362: #VALUE! | Z362: Brentford | AC362: 36 | AD362: Manchester City | AE362: #VALUE! | AH362: #VALUE! | AI362: Brentford
B363: 36 | C363: Nottingham Forest | D363: #VALUE! | E363: 1 | F363: 1 | G363: #VALUE! | H363: Newcastle | K363: 36 | L363: Nottingham Forest | M363: #VALUE! | P363: #VALUE! | Q363: Newcastle | T363: 36 | U363: Nottingham Forest | V363: #VALUE! | Y363: #VALUE! | Z363: Newcastle | AC363: 36 | AD363: Nottingham Forest | AE363: #VALUE! | AH363: #VALUE! | AI363: Newcastle
B364: 36 | C364: Sunderland | D364: #VALUE! | E364: 0 | F364: 2 | G364: #VALUE! | H364: Manchester United | K364: 36 | L364: Sunderland | M364: #VALUE! | P364: #VALUE! | Q364: Manchester United | T364: 36 | U364: Sunderland | V364: #VALUE! | Y364: #VALUE! | Z364: Manchester United | AC364: 36 | AD364: Sunderland | AE364: #VALUE! | AH364: #VALUE! | AI364: Manchester United
B365: 36 | C365: Tottenham | D365: #VALUE! | E365: 1 | F365: 1 | G365: #VALUE! | H365: Leeds | K365: 36 | L365: Tottenham | M365: #VALUE! | P365: #VALUE! | Q365: Leeds | T365: 36 | U365: Tottenham | V365: #VALUE! | Y365: #VALUE! | Z365: Leeds | AC365: 36 | AD365: Tottenham | AE365: #VALUE! | AH365: #VALUE! | AI365: Leeds
B366: 36 | C366: West Ham | D366: #VALUE! | E366: 1 | F366: 2 | G366: #VALUE! | H366: Arsenal | K366: 36 | L366: West Ham | M366: #VALUE! | P366: #VALUE! | Q366: Arsenal | T366: 36 | U366: West Ham | V366: #VALUE! | Y366: #VALUE! | Z366: Arsenal | AC366: 36 | AD366: West Ham | AE366: #VALUE! | AH366: #VALUE! | AI366: Arsenal
B367: 37 | C367: Bournemouth | D367: #VALUE! | G367: #VALUE! | H367: Manchester City | K367: 37 | L367: Bournemouth | M367: #VALUE! | P367: #VALUE! | Q367: Manchester City | T367: 37 | U367: Bournemouth | V367: #VALUE! | Y367: #VALUE! | Z367: Manchester City | AC367: 37 | AD367: Bournemouth | AE367: #VALUE! | AH367: #VALUE! | AI367: Manchester City
...

Sheet Star Man
B2: ✭VAS STAR MAN SELECTIONS✭ | J2: ✭TOM STAR MAN SELECTIONS✭
B4: GW | C4: Star Man | D4: #VALUE! | E4: #VALUE! | F4: #VALUE! | G4: #VALUE! | H4: Pts | J4: GW | K4: Star Man | L4: #VALUE! | M4: #VALUE! | N4: #VALUE! | O4: #VALUE! | P4: Pts
B5: 1 | C5: Hugo Ekitike | D5: 1 | E5: 1 | F5: 0 | G5: 0 | H5: =SUM(E79:H79) -> 4 | J5: 1 | K5: Erling Haaland | L5: 2 | M5: 0 | N5: 0 | O5: 0 | P5: =SUM(M79:P79) -> 6
B6: 2 | C6: Chris Wood | D6: 0 | E6: 0 | F6: 0 | G6: 0 | H6: =SUM(E80:H80) -> 0 | J6: 2 | K6: Mohamed Salah | L6: 0 | M6: 1 | N6: 0 | O6: 0 | P6: =SUM(M80:P80) -> 1
B7: 3 | C7: Richarlison | D7: 0 | E7: 0 | F7: 0 | G7: 0 | H7: =SUM(E81:H81) -> 0 | J7: 3 | K7: Joao Pedro | L7: 1 | M7: 0 | N7: 0 | O7: 0 | P7: =SUM(M81:P81) -> 3
B8: 4 | C8: Eberechi Eze | D8: 0 | E8: 1 | F8: 0 | G8: 0 | H8: =SUM(E82:H82) -> 1 | J8: 4 | K8: Viktor Gyokeres | L8: 1 | M8: 0 | N8: 0 | O8: 0 | P8: =SUM(M82:P82) -> 3
B9: 5 | C9: Jean-Philipe Mateta | D9: 1 | E9: 0 | F9: 0 | G9: 0 | H9: =SUM(E83:H83) -> 3 | J9: 5 | K9: Alexander Isak | L9: 0 | M9: 0 | N9: 0 | O9: 0 | P9: =SUM(M83:P83) -> 0
B10: 6 | C10: Antoine Semenyo | D10: 1 | E10: 0 | F10: 0 | G10: 0 | H10: =SUM(E84:H84) -> 3 | J10: 6 | K10: Bruno Fernandes | L10: 0 | M10: 0 | N10: 1 | O10: 0 | P10: =SUM(M84:P84) -> -1
B11: 7 | C11: Justin Kluivert | D11: 1 | E11: 0 | F11: 0 | G11: 0 | H11: =SUM(E85:H85) -> 3 | J11: 7 | K11: Jaidon Anthony | L11: 0 | M11: 0 | N11: 0 | O11: 0 | P11: =SUM(M85:P85) -> 0
B12: 8 | C12: Noah Okafor | D12: 0 | E12: 0 | F12: 0 | G12: 0 | H12: =SUM(E86:H86) -> 0 | J12: 8 | K12: Nick Woltemade | L12: 1 | M12: 0 | N12: 0 | O12: 0 | P12: =SUM(M86:P86) -> 3
B13: 9 | C13: Lesley Ugochukwu | D13: 0 | E13: 0 | F13: 0 | G13: 0 | H13: =SUM(E87:H87) -> 0 | J13: 9 | K13: Jarrad Bowen | L13: 0 | M13: 1 | N13: 0 | O13: 0 | P13: =SUM(M87:P87) -> 1
B14: 10 | C14: Bukayo Saka | D14: 0 | E14: 0 | F14: 0 | G14: 0 | H14: =SUM(E88:H88) -> 0 | J14: 10 | K14: Bryan Mbuembo | L14: 0 | M14: 0 | N14: 0 | O14: 0 | P14: =SUM(M88:P88) -> 0
B15: 11 | C15: Ismaïla Sarr | D15: 0 | E15: 0 | F15: 0 | G15: 0 | H15: =SUM(E89:H89) -> 0 | J15: 11 | K15: Iliman Ndiaye | L15: 0 | M15: 0 | N15: 0 | O15: 0 | P15: =SUM(M89:P89) -> 0
B16: 12 | C16: Evanilson | D16: 0 | E16: 0 | F16: 0 | G16: 0 | H16: =SUM(E90:H90) -> 0 | J16: 12 | K16: Emi Buendia | L16: 0 | M16: 0 | N16: 0 | O16: 0 | P16: =SUM(M90:P90) -> 0
... B39: 35 | C39: Michael Kayode | D39: 0 | E39: 0 | F39: 1 | G39: 0 | H39: =SUM(E113:H113) -> -1 | J39: 35 | K39: Dango Ouattara | L39: 0 | M39: 0 | N39: 0 | O39: 0 | P39: =SUM(M113:P113) -> 0
B40: 36 | C40: Jack Hinshelwood | H40: =SUM(E114:H114) -> 0 | J40: 36 | K40: Andrey Santos | P40: =SUM(M114:P114) -> 0
B41: 37 | H41: =SUM(E115:H115) -> 0 | J41: 37 | P41: =SUM(M115:P115) -> 0
B42: 38 | H42: =SUM(E116:H116) -> 0 | J42: 38 | P42: =SUM(M116:P116) -> 0
R51: VTGP | S51: VTAP | T51: VTYCP | U51: VTRCP | V51: VTSMP | X51: KEY
R52: =SUM(E79:E116) -> 33 | S52: =SUM(F79:F116) -> 6 | T52: =SUM(G79:G116) -> 0 | U52: =SUM(H79:H116) -> -3 | V52: =SUM(R52:U52) -> 36 | X52: VTGP = "Vas Total Goal Points"
X53: TTGP = "Tom Total Goal Points"
R54: TTGP | S54: TTAP | T54: TTYCP | U54: TTRCP | V54: TTSMP | X54: VTAP = "Vas Total Assist Points
R55: =SUM(M79:M116) -> 21 | S55: =SUM(M5:M42) -> 4 | T55: =SUM(N5:N42)*-1 -> -2 | U55: =SUM(O5:O42)*-3 -> 0 | V55: =SUM(R55:U55) -> 23 | X55: TTAP = "Tom Total Assist Points
X56: VTYCP = "Vas Total Yellow Card Points"
X57: TTYCP = "Tom Total Yellow Card Points"
X58: VTRCP = "Vas Total Red Card Points"
X59: TTRCP = "Tom Total Red Card Points"
X60: VTSMP = "Vas Total Star Man Points"
X61: TTSMP = "Tom Total Star Man Points"
D77: Vas Star Man Pts | L77: Tom Star Man Pts | R77: KEY
D78: GW | E78: GP | F78: AP | G78: YCP | H78: RCP | L78: GW | M78: GP | N78: AP | O78: YCP | P78: RCP | R78: GW = "Gameweek"
D79: 1 | E79: =D5*3 -> 3 | F79: =E5 -> 1 | G79: =-1*F5 -> 0 | H79: =-3*G5 -> 0 | L79: 1 | M79: =L5*3 -> 6 | N79: =M5 -> 0 | O79: =-1*N5 -> 0 | P79: =-3*O5 -> 0 | R79: GP = "Goal Points"
D80: 2 | E80: =D6*3 -> 0 | F80: =E6 -> 0 | G80: =-1*F6 -> 0 | H80: =-3*G6 -> 0 | L80: 2 | M80: =L6*3 -> 0 | N80: =M6 -> 1 | O80: =-1*N6 -> 0 | P80: =-3*O6 -> 0 | R80: AP = "Assist Points"
D81: 3 | E81: =D7*3 -> 0 | F81: =E7 -> 0 | G81: =-1*F7 -> 0 | H81: =-3*G7 -> 0 | L81: 3 | M81: =L7*3 -> 3 | N81: =M7 -> 0 | O81: =-1*N7 -> 0 | P81: =-3*O7 -> 0 | R81: YCP = "Yellow Card Points"
D82: 4 | E82: =D8*3 -> 0 | F82: =E8 -> 1 | G82: =-1*F8 -> 0 | H82: =-3*G8 -> 0 | L82: 4 | M82: =L8*3 -> 3 | N82: =M8 -> 0 | O82: =-1*N8 -> 0 | P82: =-3*O8 -> 0 | R82: RCP = "Red Card Points"
D83: 5 | E83: =D9*3 -> 3 | F83: =E9 -> 0 | G83: =-1*F9 -> 0 | H83: =-3*G9 -> 0 | L83: 5 | M83: =L9*3 -> 0 | N83: =M9 -> 0 | O83: =-1*N9 -> 0 | P83: =-3*O9 -> 0
D84: 6 | E84: =D10*3 -> 3 | F84: =E10 -> 0 | G84: =-1*F10 -> 0 | H84: =-3*G10 -> 0 | L84: 6 | M84: =L10*3 -> 0 | N84: =M10 -> 0 | O84: =-1*N10 -> -1 | P84: =-3*O10 -> 0
D85: 7 | E85: =D11*3 -> 3 | F85: =E11 -> 0 | G85: =-1*F11 -> 0 | H85: =-3*G11 -> 0 | L85: 7 | M85: =L11*3 -> 0 | N85: =M11 -> 0 | O85: =-1*N11 -> 0 | P85: =-3*O11 -> 0
D86: 8 | E86: =D12*3 -> 0 | F86: =E12 -> 0 | G86: =-1*F12 -> 0 | H86: =-3*G12 -> 0 | L86: 8 | M86: =L12*3 -> 3 | N86: =M12 -> 0 | O86: =-1*N12 -> 0 | P86: =-3*O12 -> 0
D87: 9 | E87: =D13*3 -> 0 | F87: =E13 -> 0 | G87: =-1*F13 -> 0 | H87: =-3*G13 -> 0 | L87: 9 | M87: =L13*3 -> 0 | N87: =M13 -> 1 | O87: =-1*N13 -> 0 | P87: =-3*O13 -> 0
...

Sheet Correct Scores
B2: VAS CORRECT SCORES | K2: TOM CORRECT SCORES | T2: ABBY CORRECT SCORES
B5: GW1 | C5: Brighton | D5: #VALUE! | E5: 1 | F5: - | G5: 1 | H5: #VALUE! | I5: Fulham | K5: GW5 | L5: Liverpool | M5: #VALUE! | N5: 2 | O5: - | P5: 1 | Q5: #VALUE! | R5: Everton | T5: GW1 | U5: Brighton | V5: #VALUE! | W5: 1 | X5: - | Y5: 1 | Z5: #VALUE! | AA5: Fulham
B6: GW8 | C6: Fulham | D6: =H5 -> #VALUE! | E6: 0 | G6: 1 | H6: =V14 -> #VALUE! | I6: Arsenal | K6: GW5 | L6: West Ham | M6: #VALUE! | N6: 1 | O6: - | P6: 2 | Q6: #VALUE! | R6: Crystal Palace | T6: GW3 | U6: Leeds | V6: #VALUE! | W6: 0 | X6: - | Y6: 0 | Z6: #VALUE! | AA6: Newcastle
B7: GW9 | C7: Bournemouth | D7: =M12 -> #VALUE! | E7: 2 | F7: - | G7: 0 | H7: =Q12 -> #VALUE! | I7: Nottingham Forest | K7: GW6 | L7: Nottingham Forest | M7: =Predictions!V65 -> #VALUE! | N7: 0 | O7: - | P7: 1 | Q7: =Z8 -> #VALUE! | R7: Sunderland | T7: GW4 | U7: Everton | V7: #VALUE! | W7: 0 | X7: - | Y7: 0 | Z7: #VALUE! | AA7: Aston Villa
B8: GW12 | C8: Burnley | D8: =M9 -> #VALUE! | E8: 0 | F8: - | G8: 2 | H8: =Q8 -> #VALUE! | I8: Chelsea | K8: GW8 | L8: Nottingham Forest | M8: =M7 -> #VALUE! | N8: 0 | O8: - | P8: 3 | Q8: =Z10 -> #VALUE! | R8: Chelsea | T8: GW4 | U8: Crystal Palace | V8: #VALUE! | W8: 0 | X8: - | Y8: 0 | Z8: #VALUE! | AA8: Sunderland
B9: GW12 | C9: Wolverhampton | D9: =Q10 -> #VALUE! | E9: 0 | F9: - | G9: 2 | H9: =Q6 -> #VALUE! | I9: Crystal Palace | K9: GW8 | L9: Burnley | M9: =Predictions!V78 -> #VALUE! | N9: 2 | O9: - | P9: 0 | Q9: =V6 -> #VALUE! | R9: Leeds | T9: GW4 | U9: Newcastle | V9: #VALUE! | W9: 1 | X9: - | Y9: 0 | Z9: #VALUE! | AA9: Wolverhampton
B10: GW13 | C10: Nottingham Forest | D10: =H7 -> #VALUE! | E10: 0 | G10: 2 | H10: =D5 -> #VALUE! | I10: Brighton | K10: GW8 | L10: Sunderland | M10: =Z8 -> #VALUE! | N10: 2 | O10: - | P10: 0 | Q10: =Z9 -> #VALUE! | R10: Wolverhampton | T10: GW4 | U10: Brentford | V10: #VALUE! | W10: 2 | X10: - | Y10: 2 | Z10: #VALUE! | AA10: Chelsea
B11: GW16 | C11: Liverpool | D11: =M5 -> #VALUE! | E11: 2 | F11: - | G11: 0 | H11: =H10 -> #VALUE! | I11: Brighton | K11: GW9 | L11: Newcastle | M11: =V9 -> #VALUE! | N11: 2 | O11: - | P11: 1 | Q11: =Z5 -> #VALUE! | R11: Fulham | T11: GW5 | U11: Liverpool | V11: #VALUE! | W11: 2 | X11: - | Y11: 1 | Z11: #VALUE! | AA11: Everton
B12: GW17 | C12: Manchester City | D12: =Predictions!Y161 -> #VALUE! | E12: 3 | F12: - | G12: 0 | H12: =M6 -> #VALUE! | I12: West Ham | K12: GW9 | L12: Bournemouth | M12: =Predictions!V87 -> #VALUE! | N12: 2 | O12: - | P12: 0 | Q12: =M8 -> #VALUE! | R12: Nottingham Forest | T12: GW5 | U12: West Ham | V12: #VALUE! | W12: 1 | X12: - | Y12: 2 | Z12: #VALUE! | AA12: Crystal Palace
B13: GW17 | C13: Wolverhampton | D13: =D9 -> #VALUE! | E13: 0 | F13: - | G13: 2 | H13: =M15 -> #VALUE! | I13: Brentford | K13: GW10 | L13: Burnley | M13: =M9 -> #VALUE! | N13: 0 | O13: - | P13: 2 | Q13: =V14 -> #VALUE! | R13: Arsenal | T13: GW6 | U13: Everton | V13: =Z11 -> #VALUE! | W13: 1 | X13: - | Y13: 1 | Z13: =V12 -> #VALUE! | AA13: West Ham
B14: GW17 | C14: Tottenham | D14: =M18 -> #VALUE! | E14: 1 | F14: - | G14: 2 | H14: =D11 -> #VALUE! | I14: Liverpool | K14: GW11 | L14: Chelsea | M14: =Q8 -> #VALUE! | N14: 3 | O14: - | P14: 0 | Q14: =Q10 -> #VALUE! | R14: Wolverhampton | T14: GW7 | U14: Arsenal | V14: =Predictions!V68 -> #VALUE! | W14: 2 | X14: - | Y14: 0 | Z14: =Z13 -> #VALUE! | AA14: West Ham
B15: GW21 | C15: Fulham | D15: =D6 -> #VALUE! | E15: 2 | F15: - | G15: 1 | H15: =H8 -> #VALUE! | I15: Chelsea | K15: GW13 | L15: Brentford | M15: =V10 -> #VALUE! | N15: 3 | O15: - | P15: 1 | Q15: =M13 -> #VALUE! | R15: Burnley | T15: GW7 | U15: Manchester United | V15: =Predictions!V74 -> #VALUE! | W15: 2 | X15: - | Y15: 0 | Z15: =Z8 -> #VALUE! | AA15: Sunderland
B16: GW22 | C16: Brighton | D16: =D5 -> #VALUE! | E16: 1 | F16: - | G16: 1 | H16: =M12 -> #VALUE! | I16: Bournemouth | K16: GW15 | L16: Newcastle | M16: =M11 -> #VALUE! | N16: 2 | O16: - | P16: 1 | Q16: =Q15 -> #VALUE! | R16: Burnley | T16: GW8 | U16: Tottenham | V16: =Predictions!V85 -> #VALUE! | W16: 1 | X16: - | Y16: 2 | Z16: =Z7 -> #VALUE! | AA16: Aston Villa
B17: GW24 | C17: Wolverhampton | D17: =Q10 -> #VALUE! | E17: 0 | F17: - | G17: 2 | H17: =H16 -> #VALUE! | I17: Bournemouth | K17: GW15 | L17: Fulham | M17: =Q11 -> #VALUE! | N17: 1 | O17: - | P17: 2 | Q17: =Q6 -> #VALUE! | R17: Crystal Palace | T17: GW11 | U17: Crystal Palace | V17: =V8 -> #VALUE! | W17: 0 | X17: - | Y17: 0 | Z17: =V5 -> #VALUE! | AA17: Brighton
B18: GW25 | C18: Bournemouth | D18: =D7 -> #VALUE! | E18: 1 | F18: - | G18: 1 | H18: =Q19 -> #VALUE! | I18: Aston Villa | K18: GW17 | L18: Tottenham | M18: =V16 -> #VALUE! | N18: 1 | O18: - | P18: 2 | Q18: =M5 -> #VALUE! | R18: Liverpool | T18: GW13 | U18: Crystal Palace | V18: =V17 -> #VALUE! | W18: 1 | X18: - | Y18: 2 | Z18: =V15 -> #VALUE! | AA18: Manchester United
B19: GW27 | C19: Crystal Palace | D19: =H9 -> #VALUE! | E19: 1 | F19: - | G19: 0 | H19: =D17 -> #VALUE! | I19: Wolverhampton | K19: GW18 | L19: Chelsea | M19: =Q8 -> #VALUE! | N19: 1 | O19: - | P19: 2 | Q19: =Z16 -> #VALUE! | R19: Aston Villa | T19: GW17 | U19: Bournemouth | V19: =M12 -> #VALUE! | W19: 1 | X19: - | Y19: 1 | Z19: =M9 -> #VALUE! | AA19: Burnley
B20: GW27 | C20: Nottingham Forest | D20: =D10 -> #VALUE! | E20: 0 | F20: - | G20: 1 | H20: =H14 -> #VALUE! | I20: Liverpool | K20: GW19 | L20: Nottingham Forest | M20: =M8 -> #VALUE! | N20: 0 | O20: - | P20: 2 | Q20: =Q5 -> #VALUE! | R20: Everton | T20: GW17 | U20: Brighton | V20: =V5 -> #VALUE! | W20: 0 | X20: - | Y20: 0 | Z20: =Z15 -> #VALUE! | AA20: Sunderland
B21: GW28 | C21: Bournemouth | D21: =D18 -> #VALUE! | E21: 1 | F21: - | G21: 1 | H21: =M10 -> #VALUE! | I21: Sunderland | K21: GW24 | L21: Brighton | M21: =D5 -> #VALUE! | N21: 1 | O21: - | P21: 1 | Q21: =Q20 -> #VALUE! | R21: Everton | T21: GW17 | U21: Wolverhampton | V21: =Z9 -> #VALUE! | W21: 0 | X21: - | Y21: 2 | Z21: =V10 -> #VALUE! | AA21: Brentford
B22: GW28 | C22: Brighton | D22: =D16 -> #VALUE! | E22: 2 | F22: - | G22: 1 | H22: =H7 -> #VALUE! | I22: Nottingham Forest | K22: GW24 | L22: Nottingham Forest | M22: =M8 -> #VALUE! | N22: 1 | O22: - | P22: 1 | Q22: =Q17 -> #VALUE! | R22: Crystal Palace | T22: GW19 | U22: Crystal Palace | V22: =V18 -> #VALUE! | W22: 1 | X22: - | Y22: 1 | Z22: =Z5 -> #VALUE! | AA22: Fulham
B23: GW28 | C23: Fulham | D23: =D6 -> #VALUE! | E23: 2 | F23: - | G23: 1 | H23: =D14 -> #VALUE! | I23: Tottenham | K23: GW26 | L23: Manchester City | M23: =Predictions!V262 -> #VALUE! | N23: 3 | O23: - | P23: 0 | Q23: =M17 -> #VALUE! | R23: Fulham | T23: GW21 | U23: Arsenal | V23: =V14 -> #VALUE! | W23: 0 | X23: - | Y23: 0 | Z23: =V11 -> #VALUE! | AA23: Liverpool
B24: GW28 | C24: Arsenal | D24: =H6 -> #VALUE! | E24: 2 | F24: - | G24: 1 | H24: =H8 -> #VALUE! | I24: Chelsea | K24: GW27 | L24: Nottingham Forest | M24: =M22 -> #VALUE! | N24: 0 | O24: - | P24: 1 | Q24: =Q18 -> #VALUE! | R24: Liverpool | T24: GW22 | U24: Leeds | V24: =V6 -> #VALUE! | W24: 1 | X24: - | Y24: 0 | Z24: =Z22 -> #VALUE! | AA24: Fulham
B25: GW31 | C25: Aston Villa | D25: =H18 -> #VALUE! | E25: 2 | F25: - | G25: 0 | H25: =H12 -> #VALUE! | I25: West Ham | K25: GW28 | L25: Fulham | M25: =Q23 -> #VALUE! | N25: 2 | O25: - | P25: 1 | Q25: =M18 -> #VALUE! | R25: Tottenham | T25: GW24 | U25: Nottingham Forest | V25: =M22 -> #VALUE! | W25: 1 | X25: - | Y25: 1 | Z25: =Z12 -> #VALUE! | AA25: Crystal Palace
B26: GW32 | C26: Chelsea | D26: =H24 -> #VALUE! | E26: 0 | F26: - | G26: 3 | H26: =D12 -> #VALUE! | I26: Manchester City | K26: GW32 | L26: Burnley | M26: =Q16 -> #VALUE! | N26: 0 | O26: - | P26: 2 | Q26: =M21 -> #VALUE! | R26: Brighton | T26: GW26 | U26: Chelsea | V26: =Z10 -> #VALUE! | W26: 2 | X26: - | Y26: 2 | Z26: =V6 -> #VALUE! | AA26: Leeds
B27: GW33 | C27: Leeds | D27: =Q9 -> #VALUE! | E27: 3 | F27: - | G27: 0 | H27: =H19 -> #VALUE! | I27: Wolverhampton | K27: GW32 | L27: Brentford | M27: =M15 -> #VALUE! | N27: 2 | O27: - | P27: 2 | Q27: =Q21 -> #VALUE! | R27: Everton | T27: GW26 | U27: West Ham | V27: =V12 -> #VALUE! | W27: 1 | X27: - | Y27: 1 | Z27: =Z18 -> #VALUE! | AA27: Manchester United
K28: GW33 | L28: Everton | M28: =Q27 -> #VALUE! | N28: 1 | O28: - | P28: 2 | Q28: =Q24 -> #VALUE! | R28: Liverpool | T28: GW27 | U28: Chelsea | V28: =V26 -> #VALUE! | W28: 1 | X28: - | Y28: 1 | Z28: =Z19 -> #VALUE! | AA28: Burnley
T29: GW28 | U29: Bournemouth | V29: =V19 -> #VALUE! | W29: 1 | X29: - | Y29: 1 | Z29: =Z20 -> #VALUE! | AA29: Sunderland
T30: GW28 | U30: Arsenal | V30: =V23 -> #VALUE! | W30: 2 | X30: - | Y30: 1 | Z30: =Z10 -> #VALUE! | AA30: Chelsea
T31: GW30 | U31: Nottingham Forest | V31: =V25 -> #VALUE! | W31: 0 | X31: - | Y31: 0 | Z31: =Z24 -> #VALUE! | AA31: Fulham
T32: GW30 | U32: Liverpool | V32: =Z23 -> #VALUE! | W32: 1 | X32: - | Y32: 1 | Z32: =V16 -> #VALUE! | AA32: Tottenham
T33: GW30 | U33: Burnley | V33: =Z28 -> #VALUE! | W33: 0 | X33: - | Y33: 0 | Z33: =V29 -> #VALUE! | AA33: Bournemouth

Sheet Vas Detailed Stats
C2: GAMEWEEK | D2: GW1 | E2: GW2 | F2: GW3 | G2: GW4 | H2: GW5 | I2: GW6 | J2: GW7 | K2: GW8 | L2: GW9 | M2: GW10 | N2: GW11 | O2: GW12 | P2: GW13 | Q2: GW14 | R2: GW15 | S2: GW16 | T2: GW17 | U2: GW18 | V2: GW19 | W2: GW20 | X2: GW21 | Y2: GW22 | Z2: GW23 | AA2: GW24 | AB2: GW25 | AC2: GW26 | AD2: GW27 | AE2: GW28 | AF2: GW29 | AG2: GW30 | AH2: GW31 | AI2: GW32 | AJ2: GW33 | AK2: GW34 | AL2: GW35 | AM2: GW36 | AN2: GW37 | AO2: GW38
B3: #VALUE! | C3: Vas Ultimate Champion Pts | D3: =Predictions!AE407 -> 11 | E3: =Predictions!AE408 -> 4 | F3: =Predictions!AE409 -> 4 | G3: =Predictions!AE410 -> 6 | H3: =Predictions!AE411 -> 6 | I3: =Predictions!AE412 -> 6 | J3: =Predictions!AE413 -> 7 | K3: =Predictions!AE414 -> 7 | L3: =Predictions!AE415 -> 7 | M3: =Predictions!AE416 -> 5 | N3: =Predictions!AE417 -> 4 | O3: =Predictions!AE418 -> 7 | P3: =Predictions!AE419 -> 7 | Q3: =Predictions!AE420 -> 10 | R3: =Predictions!AE421 -> 4 | S3: =Predictions!AE422 -> 12 | T3: =Predictions!AE423 -> 13 | U3: =Predictions!AE424 -> 9 | V3: =Predictions!AE425 -> 2 | W3: =Predictions!AE426 -> 6 | X3: =Predictions!AE427 -> 4 | Y3: =Predictions!AE428 -> 6 | Z3: =Predictions!AE429 -> 8 | AA3: =Predictions!AE430 -> 8 | AB3: =Predictions!AE431 -> 10 | AC3: =Predictions!AE432 -> 4 | AD3: =Predictions!AE433 -> 8 | AE3: =Predictions!AE434 -> 16 | AF3: =Predictions!AE435 -> 3 | AG3: =Predictions!AE436 -> 3 | AH3: =Predictions!AE437 -> 4 | AI3: =Predictions!AE438 -> 7 | AJ3: =Predictions!AE439 -> 6 | AK3: =Predictions!AE440 -> 4 | AL3: =Predictions!AE441 -> 3 | AM3: =Predictions!AE442 -> #N/A | AN3: =Predictions!AE443 -> #N/A | AO3: =Predictions!AE444 -> #N/A
B4: #VALUE! | C4: Vas Ultimate Champion Total Pts | D4: =D3 -> 11 | E4: =D4+E3 -> 15 | F4: =E4+F3 -> 19 | G4: =F4+G3 -> 25 | H4: =G4+H3 -> 31 | I4: =H4+I3 -> 37 | J4: =I4+J3 -> 44 | K4: =J4+K3 -> 51 | L4: =K4+L3 -> 58 | ... AO4: =AN4+AO3 -> #N/A
B5: #VALUE! | C5: Vas Prediction League Pts | D5: =Predictions!AH407 -> 7 | E5: =Predictions!AH408 -> 4 | F5: =Predictions!AH409 -> 4 | G5: =Predictions!AH410 -> 5 | H5: =Predictions!AH411 -> 3 | I5: =Predictions!AH412 -> 3 | J5: =Predictions!AH413 -> 4 | K5: =Predictions!AH414 -> 7 | L5: =Predictions!AH415 -> 7 | M5: =Predictions!AH416 -> 5 | N5: =Predictions!AH417 -> 4 | O5: =Predictions!AH418 -> 7 | P5: =Predictions!AH419 -> 7 | Q5: =Predictions!AH420 -> 4 | R5: =Predictions!AH421 -> 4 | S5: =Predictions!AH422 -> 9 | T5: =Predictions!AH423 -> 13 | U5: =Predictions!AH424 -> 5 | V5: =Predictions!AH425 -> 2 | W5: =Predictions!AH426 -> 5 | X5: =Predictions!AH427 -> 6 | Y5: =Predictions!AH428 -> 3 | Z5: =Predictions!AH429 -> 4 | AA5: =Predictions!AH430 -> 8 | AB5: =Predictions!AH431 -> 7 | AC5: =Predictions!AH432 -> 3 | AD5: =Predictions!AH433 -> 8 | AE5: =Predictions!AH434 -> 16 | AF5: =Predictions!AH435 -> 3 | AG5: =Predictions!AH436 -> 3 | AH5: =Predictions!AH437 -> 4 | AI5: =Predictions!AH438 -> 7 | AJ5: =Predictions!AH439 -> 6 | AK5: =Predictions!AH440 -> 4 | AL5: =Predictions!AH441 -> 4 | AM5: =Predictions!AH442 -> 0 | AN5: =Predictions!AH443 -> 0 | AO5: =Predictions!AH444 -> 0
B6: #VALUE! | C6: Vas Prediction League Total Pts | D6: =D5 -> 7 | E6: =D6+E5 -> 11 | F6: =E6+F5 -> 15 | G6: =F6+G5 -> 20 | H6: =G6+H5 -> 23 | I6: =H6+I5 -> 26 | J6: =I6+J5 -> 30 | K6: =J6+K5 -> 37 | L6: =K6+L5 -> 44 | ... AO6: =AN6+AO5 -> 195
B7: #VALUE! | C7: Vas Star Man Pts | D7: ='Star Man'!H5 -> 4 | E7: ='Star Man'!H6 -> 0 | F7: ='Star Man'!H7 -> 0 | G7: ='Star Man'!H8 -> 1 | H7: ='Star Man'!H9 -> 3 | I7: ='Star Man'!H10 -> 3 | J7: ='Star Man'!H11 -> 3 | K7: ='Star Man'!H12 -> 0 | L7: ='Star Man'!H13 -> 0 | M7: ='Star Man'!H14 -> 0 | N7: ='Star Man'!H15 -> 0 | O7: ='Star Man'!H16 -> 0 | P7: ='Star Man'!H17 -> 0 | Q7: ='Star Man'!H18 -> 6 | R7: ='Star Man'!H19 -> 0 | S7: ='Star Man'!H20 -> 3 | T7: ='Star Man'!H21 -> 0 | U7: ='Star Man'!H22 -> 4 | V7: ='Star Man'!H23 -> 0 | W7: ='Star Man'!H24 -> 1 | X7: ='Star Man'!H25 -> -2 | Y7: ='Star Man'!H26 -> 3 | Z7: ='Star Man'!H27 -> 4 | AA7: ='Star Man'!H28 -> 0 | AB7: ='Star Man'!H29 -> 3 | AC7: ='Star Man'!H30 -> 1 | AD7: ='Star Man'!H31 -> 0 | AE7: ='Star Man'!H32 -> 0 | AF7: ='Star Man'!H33 -> 0 | AG7: ='Star Man'!H34 -> 0 | AH7: ='Star Man'!H35 -> 0 | AI7: ='Star Man'!H36 -> 0 | AJ7: ='Star Man'!H37 -> 0 | AK7: ='Star Man'!H38 -> 0 | AL7: ='Star Man'!H39 -> -1 | AM7: ='Star Man'!H40 -> 0 | AN7: ='Star Man'!H41 -> 0 | AO7: ='Star Man'!H42 -> 0
B8: #VALUE! | C8: Vas Star Man Total Pts | D8: =D7 -> 4 | E8: =D8+E7 -> 4 | F8: =E8+F7 -> 4 | G8: =F8+G7 -> 5 | H8: =G8+H7 -> 8 | I8: =H8+I7 -> 11 | J8: =I8+J7 -> 14 | K8: =J8+K7 -> 14 | L8: =K8+L7 -> 14 | ... AO8: =AN8+AO7 -> 36
B9: #VALUE! | C9: Vas Correct Scores | D9: =Predictions!U407/2 -> 1 | E9: =Predictions!U408/2 -> 0 | F9: =Predictions!U409/2 -> 0 | G9: =Predictions!U410/2 -> 0 | H9: =Predictions!U411/2 -> 0 | I9: =Predictions!U412/2 -> 0 | J9: =Predictions!U413/2 -> 0 | K9: =Predictions!U414/2 -> 1 | L9: =Predictions!U415/2 -> 1 | M9: =Predictions!U416/2 -> 0 | N9: =Predictions!U417/2 -> 0 | O9: =Predictions!U418/2 -> 2 | P9: =Predictions!U419/2 -> 1 | Q9: =Predictions!U420/2 -> 0 | R9: =Predictions!U421/2 -> 0 | S9: =Predictions!U422/2 -> 1 | T9: =Predictions!U423/2 -> 3 | U9: =Predictions!U424/2 -> 0 | V9: =Predictions!U425/2 -> 0 | W9: =Predictions!U426/2 -> 0 | X9: =Predictions!U427/2 -> 1 | Y9: =Predictions!U428/2 -> 1 | Z9: =Predictions!U429/2 -> 0 | AA9: =Predictions!U430/2 -> 1 | AB9: =Predictions!U431/2 -> 1 | AC9: =Predictions!U432/2 -> 0 | AD9: =Predictions!U433/2 -> 2 | AE9: =Predictions!U434/2 -> 4 | AF9: =Predictions!U435/2 -> 0 | AG9: =Predictions!U436/2 -> 0 | AH9: =Predictions!U437/2 -> 1 | AI9: =Predictions!U438/2 -> 1 | AJ9: =Predictions!U439/2 -> 1 | AK9: =Predictions!U440/2 -> 0 | AL9: =Predictions!U441/2 -> 0 | AM9: =Predictions!U442/2 -> 0 | AN9: =Predictions!U443/2 -> 0 | AO9: =Predictions!U444/2 -> 0
B10: #VALUE! | C10: Vas Total Correct Scores | D10: =D9 -> 1 | E10: =D10+E9 -> 1 | F10: =E10+F9 -> 1 | G10: =F10+G9 -> 1 | H10: =G10+H9 -> 1 | I10: =H10+I9 -> 1 | J10: =I10+J9 -> 1 | K10: =J10+K9 -> 2 | L10: =K10+L9 -> 3 | ... AO10: =AN10+AO9 -> 23
B11: #VALUE! | C11: Vas Correct Results | D11: =Predictions!S407 -> 5 | E11: =Predictions!S408 -> 4 | F11: =Predictions!S409 -> 4 | G11: =Predictions!S410 -> 5 | H11: =Predictions!S411 -> 3 | I11: =Predictions!S412 -> 3 | J11: =Predictions!S413 -> 4 | K11: =Predictions!S414 -> 5 | L11: =Predictions!S415 -> 5 | M11: =Predictions!S416 -> 5 | N11: =Predictions!S417 -> 4 | O11: =Predictions!S418 -> 3 | P11: =Predictions!S419 -> 5 | Q11: =Predictions!S420 -> 4 | R11: =Predictions!S421 -> 4 | S11: =Predictions!S422 -> 7 | T11: =Predictions!S423 -> 7 | U11: =Predictions!S424 -> 5 | V11: =Predictions!S425 -> 2 | W11: =Predictions!S426 -> 5 | X11: =Predictions!S427 -> 4 | Y11: =Predictions!S428 -> 1 | Z11: =Predictions!S429 -> 4 | AA11: =Predictions!S430 -> 6 | AB11: =Predictions!S431 -> 5 | AC11: =Predictions!S432 -> 3 | AD11: =Predictions!S433 -> 4 | AE11: =Predictions!S434 -> 8 | AF11: =Predictions!S435 -> 3 | AG11: =Predictions!S436 -> 3 | AH11: =Predictions!S437 -> 2 | AI11: =Predictions!S438 -> 5 | AJ11: =Predictions!S439 -> 4 | AK11: =Predictions!S440 -> 4 | AL11: =Predictions!S441 -> 4 | AM11: =Predictions!S442 -> 0 | AN11: =Predictions!S443 -> 0 | AO11: =Predictions!S444 -> 0
B12: #VALUE! | C12: Vas Total Correct Results | D12: =D11 -> 5 | E12: =D12+E11 -> 9 | F12: =E12+F11 -> 13 | G12: =F12+G11 -> 18 | H12: =G12+H11 -> 21 | I12: =H12+I11 -> 24 | J12: =I12+J11 -> 28 | K12: =J12+K11 -> 33 | L12: =K12+L11 -> 38 | ... AO12: =AN12+AO11 -> 149
B13: #VALUE! | C13: Vas Star Man Goals | D13: ='Star Man'!D5 -> 1 | E13: ='Star Man'!D6 -> 0 | F13: ='Star Man'!D7 -> 0 | G13: ='Star Man'!D8 -> 0 | H13: ='Star Man'!D9 -> 1 | I13: ='Star Man'!D10 -> 1 | J13: ='Star Man'!D11 -> 1 | K13: ='Star Man'!D12 -> 0 | L13: ='Star Man'!D13 -> 0 | M13: ='Star Man'!D14 -> 0 | N13: ='Star Man'!D15 -> 0 | O13: ='Star Man'!D16 -> 0 | P13: ='Star Man'!D17 -> 0 | Q13: ='Star Man'!D18 -> 2 | R13: ='Star Man'!D19 -> 0 | S13: ='Star Man'!D20 -> 1 | T13: ='Star Man'!D21 -> 0 | U13: ='Star Man'!D22 -> 1 | V13: ='Star Man'!D23 -> 0 | W13: ='Star Man'!D24 -> 0 | X13: ='Star Man'!D25 -> 0 | Y13: ='Star Man'!D26 -> 1 | Z13: ='Star Man'!D27 -> 1 | AA13: ='Star Man'!D28 -> 0 | AB13: ='Star Man'!D29 -> 1 | AC13: ='Star Man'!D30 -> 0 | AD13: ='Star Man'!D31 -> 0 | AE13: ='Star Man'!D32 -> 0 | AF13: ='Star Man'!D33 -> 0 | AG13: ='Star Man'!D34 -> 0 | AH13: ='Star Man'!D35 -> 0 | AI13: ='Star Man'!D36 -> 0 | AJ13: ='Star Man'!D37 -> 0 | AK13: ='Star Man'!D38 -> 0 | AL13: ='Star Man'!D39 -> 0 | AM13: ='Star Man'!D40 -> 0 | AN13: ='Star Man'!D41 -> 0 | AO13: ='Star Man'!D42 -> 0
B14: #VALUE! | C14: Vas Total Star Man Goals | D14: =D13 -> 1 | E14: =D14+E13 -> 1 | F14: =E14+F13 -> 1 | G14: =F14+G13 -> 1 | H14: =G14+H13 -> 2 | I14: =H14+I13 -> 3 | J14: =I14+J13 -> 4 | K14: =J14+K13 -> 4 | L14: =K14+L13 -> 4 | ... AO14: =AN14+AO13 -> 11
B15: #VALUE! | C15: Vas Star Man Assists | D15: ='Star Man'!E5 -> 1 | E15: ='Star Man'!E6 -> 0 | F15: ='Star Man'!E7 -> 0 | G15: ='Star Man'!E8 -> 1 | H15: ='Star Man'!E9 -> 0 | I15: ='Star Man'!E10 -> 0 | J15: ='Star Man'!E11 -> 0 | K15: ='Star Man'!E12 -> 0 | L15: ='Star Man'!E13 -> 0 | M15: ='Star Man'!E14 -> 0 | N15: ='Star Man'!E15 -> 0 | O15: ='Star Man'!E16 -> 0 | P15: ='Star Man'!E17 -> 0 | Q15: ='Star Man'!E18 -> 0 | R15: ='Star Man'!E19 -> 0 | S15: ='Star Man'!E20 -> 0 | T15: ='Star Man'!E21 -> 0 | U15: ='Star Man'!E22 -> 1 | V15: ='Star Man'!E23 -> 0 | W15: ='Star Man'!E24 -> 1 | X15: ='Star Man'!E25 -> 0 | Y15: ='Star Man'!E26 -> 0 | Z15: ='Star Man'!E27 -> 1 | AA15: ='Star Man'!E28 -> 0 | AB15: ='Star Man'!E29 -> 0 | AC15: ='Star Man'!E30 -> 1 | AD15: ='Star Man'!E31 -> 0 | AE15: ='Star Man'!E32 -> 0 | AF15: ='Star Man'!E33 -> 0 | AG15: ='Star Man'!E34 -> 0 | AH15: ='Star Man'!E35 -> 0 | AI15: ='Star Man'!E36 -> 0 | AJ15: ='Star Man'!E37 -> 0 | AK15: ='Star Man'!E38 -> 0 | AL15: ='Star Man'!E39 -> 0 | AM15: ='Star Man'!E40 -> 0 | AN15: ='Star Man'!E41 -> 0 | AO15: ='Star Man'!E42 -> 0
B16: #VALUE! | C16: Vas Total Star Man Assists | D16: =D15 -> 1 | E16: =D16+E15 -> 1 | F16: =E16+F15 -> 1 | G16: =F16+G15 -> 2 | H16: =G16+H15 -> 2 | I16: =H16+I15 -> 2 | J16: =I16+J15 -> 2 | K16: =J16+K15 -> 2 | L16: =K16+L15 -> 2 | ... AO16: =AN16+AO15 -> 6
B17: #VALUE! | C17: Vas Star Man Yellows | D17: ='Star Man'!F5 -> 0 | E17: ='Star Man'!F6 -> 0 | F17: ='Star Man'!F7 -> 0 | G17: ='Star Man'!F8 -> 0 | H17: ='Star Man'!F9 -> 0 | I17: ='Star Man'!F10 -> 0 | J17: ='Star Man'!F11 -> 0 | K17: ='Star Man'!F12 -> 0 | L17: ='Star Man'!F13 -> 0 | M17: ='Star Man'!F14 -> 0 | N17: ='Star Man'!F15 -> 0 | O17: ='Star Man'!F16 -> 0 | P17: ='Star Man'!F17 -> 0 | Q17: ='Star Man'!F18 -> 0 | R17: ='Star Man'!F19 -> 0 | S17: ='Star Man'!F20 -> 0 | T17: ='Star Man'!F21 -> 0 | U17: ='Star Man'!F22 -> 0 | V17: ='Star Man'!F23 -> 0 | W17: ='Star Man'!F24 -> 0 | X17: ='Star Man'!F25 -> 1 | Y17: ='Star Man'!F26 -> 0 | Z17: ='Star Man'!F27 -> 0 | AA17: ='Star Man'!F28 -> 0 | AB17: ='Star Man'!F29 -> 0 | AC17: ='Star Man'!F30 -> 0 | AD17: ='Star Man'!F31 -> 0 | AE17: ='Star Man'!F32 -> 0 | AF17: ='Star Man'!F33 -> 0 | AG17: ='Star Man'!F34 -> 0 | AH17: ='Star Man'!F35 -> 0 | AI17: ='Star Man'!F36 -> 0 | AJ17: ='Star Man'!F37 -> 0 | AK17: ='Star Man'!F38 -> 0 | AL17: ='Star Man'!F39 -> 1 | AM17: ='Star Man'!F40 -> 0 | AN17: ='Star Man'!F41 -> 0 | AO17: ='Star Man'!F42 -> 0
B18: #VALUE! | C18: Vas Total Star Man Yellows | D18: =D17 -> 0 | E18: =D18+E17 -> 0 | F18: =E18+F17 -> 0 | G18: =F18+G17 -> 0 | H18: =G18+H17 -> 0 | I18: =H18+I17 -> 0 | J18: =I18+J17 -> 0 | K18: =J18+K17 -> 0 | L18: =K18+L17 -> 0 | ... AO18: =AN18+AO17 -> 2
B19: #VALUE! | C19: Vas Star Man Reds | D19: ='Star Man'!G5 -> 0 | E19: ='Star Man'!G6 -> 0 | F19: ='Star Man'!G7 -> 0 | G19: ='Star Man'!G8 -> 0 | H19: ='Star Man'!G9 -> 0 | I19: ='Star Man'!G10 -> 0 | J19: ='Star Man'!G11 -> 0 | K19: ='Star Man'!G12 -> 0 | L19: ='Star Man'!G13 -> 0 | M19: ='Star Man'!G14 -> 0 | N19: ='Star Man'!G15 -> 0 | O19: ='Star Man'!G16 -> 0 | P19: ='Star Man'!G17 -> 0 | Q19: ='Star Man'!G18 -> 0 | R19: ='Star Man'!G19 -> 0 | S19: ='Star Man'!G20 -> 0 | T19: ='Star Man'!G21 -> 0 | U19: ='Star Man'!G22 -> 0 | V19: ='Star Man'!G23 -> 0 | W19: ='Star Man'!G24 -> 0 | X19: ='Star Man'!G25 -> 1 | Y19: ='Star Man'!G26 -> 0 | Z19: ='Star Man'!G27 -> 0 | AA19: ='Star Man'!G28 -> 0 | AB19: ='Star Man'!G29 -> 0 | AC19: ='Star Man'!G30 -> 0 | AD19: ='Star Man'!G31 -> 0 | AE19: ='Star Man'!G32 -> 0 | AF19: ='Star Man'!G33 -> 0 | AG19: ='Star Man'!G34 -> 0 | AH19: ='Star Man'!G35 -> 0 | AI19: ='Star Man'!G36 -> 0 | AJ19: ='Star Man'!G37 -> 0 | AK19: ='Star Man'!G38 -> 0 | AL19: ='Star Man'!G39 -> 0 | AM19: ='Star Man'!G40 -> 0 | AN19: ='Star Man'!G41 -> 0 | AO19: ='Star Man'!G42 -> 0
B20: #VALUE! | C20: Vas Total Star Man Reds | D20: =D19 -> 0 | E20: =D20+E19 -> 0 | F20: =E20+F19 -> 0 | G20: =F20+G19 -> 0 | H20: =G20+H19 -> 0 | I20: =H20+I19 -> 0 | J20: =I20+J19 -> 0 | K20: =J20+K19 -> 0 | L20: =K20+L19 -> 0 | ... AO20: =AN20+AO19 -> 1
C21: GAMEWEEK | D21: GW1 | E21: GW2 | F21: GW3 | G21: GW4 | H21: GW5 | I21: GW6 | J21: GW7 | K21: GW8 | L21: GW9 | M21: GW10 | N21: GW11 | O21: GW12 | P21: GW13 | Q21: GW14 | R21: GW15 | S21: GW16 | T21: GW17 | U21: GW18 | V21: GW19 | W21: GW20 | X21: GW21 | Y21: GW22 | Z21: GW23 | AA21: GW24 | AB21: GW25 | AC21: GW26 | AD21: GW27 | AE21: GW28 | AF21: GW29 | AG21: GW30 | AH21: GW31 | AI21: GW32 | AJ21: GW33 | AK21: GW34 | AL21: GW35 | AM21: GW36 | AN21: GW37 | AO21: GW38

Sheet Tom Detailed Stats
C2: GAMEWEEK | D2: GW1 | E2: GW2 | F2: GW3 | G2: GW4 | H2: GW5 | I2: GW6 | J2: GW7 | K2: GW8 | L2: GW9 | M2: GW10 | N2: GW11 | O2: GW12 | P2: GW13 | Q2: GW14 | R2: GW15 | S2: GW16 | T2: GW17 | U2: GW18 | V2: GW19 | W2: GW20 | X2: GW21 | Y2: GW22 | Z2: GW23 | AA2: GW24 | AB2: GW25 | AC2: GW26 | AD2: GW27 | AE2: GW28 | AF2: GW29 | AG2: GW30 | AH2: GW31 | AI2: GW32 | AJ2: GW33 | AK2: GW34 | AL2: GW35 | AM2: GW36 | AN2: GW37 | AO2: GW38
B3: #VALUE! | C3: Tom Ultimate Champion Pts | D3: =Predictions!AF407 -> 9 | E3: =Predictions!AF408 -> 5 | F3: =Predictions!AF409 -> 6 | G3: =Predictions!AF410 -> 9 | H3: =Predictions!AF411 -> 7 | I3: =Predictions!AF412 -> 4 | J3: =Predictions!AF413 -> 7 | K3: =Predictions!AF414 -> 16 | L3: =Predictions!AF415 -> 9 | M3: =Predictions!AF416 -> 7 | N3: =Predictions!AF417 -> 9 | O3: =Predictions!AF418 -> 5 | P3: =Predictions!AF419 -> 13 | Q3: =Predictions!AF420 -> 5 | R3: =Predictions!AF421 -> 10 | S3: =Predictions!AF422 -> 5 | T3: =Predictions!AF423 -> 5 | U3: =Predictions!AF424 -> 8 | V3: =Predictions!AF425 -> 4 | W3: =Predictions!AF426 -> 6 | X3: =Predictions!AF427 -> 1 | Y3: =Predictions!AF428 -> 1 | Z3: =Predictions!AF429 -> 3 | AA3: =Predictions!AF430 -> 12 | AB3: =Predictions!AF431 -> 3 | AC3: =Predictions!AF432 -> 4 | AD3: =Predictions!AF433 -> 7 | AE3: =Predictions!AF434 -> 7 | AF3: =Predictions!AF435 -> 2 | AG3: =Predictions!AF436 -> 4 | AH3: =Predictions!AF437 -> 3 | AI3: =Predictions!AF438 -> 9 | AJ3: =Predictions!AF439 -> 7 | AK3: =Predictions!AF440 -> 5 | AL3: =Predictions!AF441 -> 4 | AM3: =Predictions!AF442 -> #N/A | AN3: =Predictions!AF443 -> #N/A | AO3: =Predictions!AF444 -> #N/A
B4: #VALUE! | C4: Tom Ultimate Champion Total Pts | D4: =D3 -> 9 | E4: =D4+E3 -> 14 | F4: =E4+F3 -> 20 | G4: =F4+G3 -> 29 | H4: =G4+H3 -> 36 | I4: =H4+I3 -> 40 | J4: =I4+J3 -> 47 | K4: =J4+K3 -> 63 | L4: =K4+L3 -> 72 | ... AO4: =AN4+AO3 -> #N/A
B5: #VALUE! | C5: Tom Prediction League Pts | D5: =Predictions!AI407 -> 3 | E5: =Predictions!AI408 -> 4 | F5: =Predictions!AI409 -> 3 | G5: =Predictions!AI410 -> 6 | H5: =Predictions!AI411 -> 7 | I5: =Predictions!AI412 -> 5 | J5: =Predictions!AI413 -> 7 | K5: =Predictions!AI414 -> 13 | L5: =Predictions!AI415 -> 8 | M5: =Predictions!AI416 -> 7 | N5: =Predictions!AI417 -> 9 | O5: =Predictions!AI418 -> 5 | P5: =Predictions!AI419 -> 7 | Q5: =Predictions!AI420 -> 5 | R5: =Predictions!AI421 -> 10 | S5: =Predictions!AI422 -> 5 | T5: =Predictions!AI423 -> 6 | U5: =Predictions!AI424 -> 8 | V5: =Predictions!AI425 -> 4 | W5: =Predictions!AI426 -> 6 | X5: =Predictions!AI427 -> 1 | Y5: =Predictions!AI428 -> 1 | Z5: =Predictions!AI429 -> 3 | AA5: =Predictions!AI430 -> 12 | AB5: =Predictions!AI431 -> 3 | AC5: =Predictions!AI432 -> 4 | AD5: =Predictions!AI433 -> 7 | AE5: =Predictions!AI434 -> 7 | AF5: =Predictions!AI435 -> 2 | AG5: =Predictions!AI436 -> 4 | AH5: =Predictions!AI437 -> 3 | AI5: =Predictions!AI438 -> 8 | AJ5: =Predictions!AI439 -> 7 | AK5: =Predictions!AI440 -> 4 | AL5: =Predictions!AI441 -> 4 | AM5: =Predictions!AI442 -> 0 | AN5: =Predictions!AI443 -> 0 | AO5: =Predictions!AI444 -> 0
B6: #VALUE! | C6: Tom Prediction League Total Pts | D6: =D5 -> 3 | E6: =D6+E5 -> 7 | F6: =E6+F5 -> 10 | G6: =F6+G5 -> 16 | H6: =G6+H5 -> 23 | I6: =H6+I5 -> 28 | J6: =I6+J5 -> 35 | K6: =J6+K5 -> 48 | L6: =K6+L5 -> 56 | ... AO6: =AN6+AO5 -> 198
B7: #VALUE! | C7: Tom Star Man Pts | D7: ='Star Man'!P5 -> 6 | E7: ='Star Man'!P6 -> 1 | F7: ='Star Man'!P7 -> 3 | G7: ='Star Man'!P8 -> 3 | H7: ='Star Man'!P9 -> 0 | I7: ='Star Man'!P10 -> -1 | J7: ='Star Man'!P11 -> 0 | K7: ='Star Man'!P12 -> 3 | L7: ='Star Man'!P13 -> 1 | M7: ='Star Man'!P14 -> 0 | N7: ='Star Man'!P15 -> 0 | O7: ='Star Man'!P16 -> 0 | P7: ='Star Man'!P17 -> 6 | Q7: ='Star Man'!P18 -> 0 | R7: ='Star Man'!P19 -> 0 | S7: ='Star Man'!P20 -> 0 | T7: ='Star Man'!P21 -> -1 | U7: ='Star Man'!P22 -> 0 | V7: ='Star Man'!P23 -> 0 | W7: ='Star Man'!P24 -> 0 | X7: ='Star Man'!P25 -> 0 | Y7: ='Star Man'!P26 -> 0 | Z7: ='Star Man'!P27 -> 0 | AA7: ='Star Man'!P28 -> 0 | AB7: ='Star Man'!P29 -> 0 | AC7: ='Star Man'!P30 -> 0 | AD7: ='Star Man'!P31 -> 0 | AE7: ='Star Man'!P32 -> 0 | AF7: ='Star Man'!P33 -> 0 | AG7: ='Star Man'!P34 -> 0 | AH7: ='Star Man'!P35 -> 0 | AI7: ='Star Man'!P36 -> 1 | AJ7: ='Star Man'!P37 -> 0 | AK7: ='Star Man'!P38 -> 1 | AL7: ='Star Man'!P39 -> 0 | AM7: ='Star Man'!P40 -> 0 | AN7: ='Star Man'!P41 -> 0 | AO7: ='Star Man'!P42 -> 0
B8: #VALUE! | C8: Tom Star Man Total Pts | D8: =D7 -> 6 | E8: =D8+E7 -> 7 | F8: =E8+F7 -> 10 | G8: =F8+G7 -> 13 | H8: =G8+H7 -> 13 | I8: =H8+I7 -> 12 | J8: =I8+J7 -> 12 | K8: =J8+K7 -> 15 | L8: =K8+L7 -> 16 | ... AO8: =AN8+AO7 -> 23
B9: #VALUE! | C9: Tom Correct Scores | D9: =Predictions!V407/2 -> 0 | E9: =Predictions!V408/2 -> 0 | F9: =Predictions!V409/2 -> 0 | G9: =Predictions!V410/2 -> 0 | H9: =Predictions!V411/2 -> 2 | I9: =Predictions!V412/2 -> 1 | J9: =Predictions!V413/2 -> 0 | K9: =Predictions!V414/2 -> 3 | L9: =Predictions!V415/2 -> 2 | M9: =Predictions!V416/2 -> 1 | N9: =Predictions!V417/2 -> 1 | O9: =Predictions!V418/2 -> 0 | P9: =Predictions!V419/2 -> 1 | Q9: =Predictions!V420/2 -> 0 | R9: =Predictions!V421/2 -> 2 | S9: =Predictions!V422/2 -> 0 | T9: =Predictions!V423/2 -> 1 | U9: =Predictions!V424/2 -> 1 | V9: =Predictions!V425/2 -> 1 | W9: =Predictions!V426/2 -> 0 | X9: =Predictions!V427/2 -> 0 | Y9: =Predictions!V428/2 -> 0 | Z9: =Predictions!V429/2 -> 0 | AA9: =Predictions!V430/2 -> 2 | AB9: =Predictions!V431/2 -> 0 | AC9: =Predictions!V432/2 -> 1 | AD9: =Predictions!V433/2 -> 1 | AE9: =Predictions!V434/2 -> 1 | AF9: =Predictions!V435/2 -> 0 | AG9: =Predictions!V436/2 -> 0 | AH9: =Predictions!V437/2 -> 0 | AI9: =Predictions!V438/2 -> 2 | AJ9: =Predictions!V439/2 -> 1 | AK9: =Predictions!V440/2 -> 0 | AL9: =Predictions!V441/2 -> 0 | AM9: =Predictions!V442/2 -> 0 | AN9: =Predictions!V443/2 -> 0 | AO9: =Predictions!V444/2 -> 0
B10: #VALUE! | C10: Tom Total Correct Scores | D10: =D9 -> 0 | E10: =D10+E9 -> 0 | F10: =E10+F9 -> 0 | G10: =F10+G9 -> 0 | H10: =G10+H9 -> 2 | I10: =H10+I9 -> 3 | J10: =I10+J9 -> 3 | K10: =J10+K9 -> 6 | L10: =K10+L9 -> 8 | ... AO10: =AN10+AO9 -> 24
B11: #VALUE! | C11: Tom Correct Results | D11: =Predictions!T407 -> 3 | E11: =Predictions!T408 -> 4 | F11: =Predictions!T409 -> 3 | G11: =Predictions!T410 -> 6 | H11: =Predictions!T411 -> 3 | I11: =Predictions!T412 -> 3 | J11: =Predictions!T413 -> 7 | K11: =Predictions!T414 -> 7 | L11: =Predictions!T415 -> 4 | M11: =Predictions!T416 -> 5 | N11: =Predictions!T417 -> 7 | O11: =Predictions!T418 -> 5 | P11: =Predictions!T419 -> 5 | Q11: =Predictions!T420 -> 5 | R11: =Predictions!T421 -> 6 | S11: =Predictions!T422 -> 5 | T11: =Predictions!T423 -> 4 | U11: =Predictions!T424 -> 6 | V11: =Predictions!T425 -> 2 | W11: =Predictions!T426 -> 6 | X11: =Predictions!T427 -> 1 | Y11: =Predictions!T428 -> 1 | Z11: =Predictions!T429 -> 3 | AA11: =Predictions!T430 -> 8 | AB11: =Predictions!T431 -> 3 | AC11: =Predictions!T432 -> 2 | AD11: =Predictions!T433 -> 5 | AE11: =Predictions!T434 -> 5 | AF11: =Predictions!T435 -> 2 | AG11: =Predictions!T436 -> 4 | AH11: =Predictions!T437 -> 3 | AI11: =Predictions!T438 -> 4 | AJ11: =Predictions!T439 -> 5 | AK11: =Predictions!T440 -> 4 | AL11: =Predictions!T441 -> 4 | AM11: =Predictions!T442 -> 0 | AN11: =Predictions!T443 -> 0 | AO11: =Predictions!T444 -> 0
B12: #VALUE! | C12: Tom Total Correct Results | D12: =D11 -> 3 | E12: =D12+E11 -> 7 | F12: =E12+F11 -> 10 | G12: =F12+G11 -> 16 | H12: =G12+H11 -> 19 | I12: =H12+I11 -> 22 | J12: =I12+J11 -> 29 | K12: =J12+K11 -> 36 | L12: =K12+L11 -> 40 | ... AO12: =AN12+AO11 -> 150
B13: #VALUE! | C13: Tom Star Man Goals | D13: ='Star Man'!L5 -> 2 | E13: ='Star Man'!L6 -> 0 | F13: ='Star Man'!L7 -> 1 | G13: ='Star Man'!L8 -> 1 | H13: ='Star Man'!L9 -> 0 | I13: ='Star Man'!L10 -> 0 | J13: ='Star Man'!L11 -> 0 | K13: ='Star Man'!L12 -> 1 | L13: ='Star Man'!L13 -> 0 | M13: ='Star Man'!L14 -> 0 | N13: ='Star Man'!L15 -> 0 | O13: ='Star Man'!L16 -> 0 | P13: ='Star Man'!L17 -> 2 | Q13: ='Star Man'!L18 -> 0 | R13: ='Star Man'!L19 -> 0 | S13: ='Star Man'!L20 -> 0 | T13: ='Star Man'!L21 -> 0 | U13: ='Star Man'!L22 -> 0 | V13: ='Star Man'!L23 -> 0 | W13: ='Star Man'!L24 -> 0 | X13: ='Star Man'!L25 -> 0 | Y13: ='Star Man'!L26 -> 0 | Z13: ='Star Man'!L27 -> 0 | AA13: ='Star Man'!L28 -> 0 | AB13: ='Star Man'!L29 -> 0 | AC13: ='Star Man'!L30 -> 0 | AD13: ='Star Man'!L31 -> 0 | AE13: ='Star Man'!L32 -> 0 | AF13: ='Star Man'!L33 -> 0 | AG13: ='Star Man'!L34 -> 0 | AH13: ='Star Man'!L35 -> 0 | AI13: ='Star Man'!L36 -> 0 | AJ13: ='Star Man'!L37 -> 0 | AK13: ='Star Man'!L38 -> 0 | AL13: ='Star Man'!L39 -> 0 | AM13: ='Star Man'!L40 -> 0 | AN13: ='Star Man'!L41 -> 0 | AO13: ='Star Man'!L42 -> 0
B14: #VALUE! | C14: Tom Total Star Man Goals | D14: =D13 -> 2 | E14: =D14+E13 -> 2 | F14: =E14+F13 -> 3 | G14: =F14+G13 -> 4 | H14: =G14+H13 -> 4 | I14: =H14+I13 -> 4 | J14: =I14+J13 -> 4 | K14: =J14+K13 -> 5 | L14: =K14+L13 -> 5 | ... AO14: =AN14+AO13 -> 7
B15: #VALUE! | C15: Tom Star Man Assists | D15: ='Star Man'!M5 -> 0 | E15: ='Star Man'!M6 -> 1 | F15: ='Star Man'!M7 -> 0 | G15: ='Star Man'!M8 -> 0 | H15: ='Star Man'!M9 -> 0 | I15: ='Star Man'!M10 -> 0 | J15: ='Star Man'!M11 -> 0 | K15: ='Star Man'!M12 -> 0 | L15: ='Star Man'!M13 -> 1 | M15: ='Star Man'!M14 -> 0 | N15: ='Star Man'!M15 -> 0 | O15: ='Star Man'!M16 -> 0 | P15: ='Star Man'!M17 -> 0 | Q15: ='Star Man'!M18 -> 0 | R15: ='Star Man'!M19 -> 0 | S15: ='Star Man'!M20 -> 0 | T15: ='Star Man'!M21 -> 0 | U15: ='Star Man'!M22 -> 0 | V15: ='Star Man'!M23 -> 0 | W15: ='Star Man'!M24 -> 0 | X15: ='Star Man'!M25 -> 0 | Y15: ='Star Man'!M26 -> 0 | Z15: ='Star Man'!M27 -> 0 | AA15: ='Star Man'!M28 -> 0 | AB15: ='Star Man'!M29 -> 0 | AC15: ='Star Man'!M30 -> 0 | AD15: ='Star Man'!M31 -> 0 | AE15: ='Star Man'!M32 -> 0 | AF15: ='Star Man'!M33 -> 0 | AG15: ='Star Man'!M34 -> 0 | AH15: ='Star Man'!M35 -> 0 | AI15: ='Star Man'!M36 -> 1 | AJ15: ='Star Man'!M37 -> 0 | AK15: ='Star Man'!M38 -> 1 | AL15: ='Star Man'!M39 -> 0 | AM15: ='Star Man'!M40 -> 0 | AN15: ='Star Man'!M41 -> 0 | AO15: ='Star Man'!M42 -> 0
B16: #VALUE! | C16: Tom Total Star Man Assists | D16: =D15 -> 0 | E16: =D16+E15 -> 1 | F16: =E16+F15 -> 1 | G16: =F16+G15 -> 1 | H16: =G16+H15 -> 1 | I16: =H16+I15 -> 1 | J16: =I16+J15 -> 1 | K16: =J16+K15 -> 1 | L16: =K16+L15 -> 2 | ... AO16: =AN16+AO15 -> 4
B17: #VALUE! | C17: Tom Star Man Yellows | D17: ='Star Man'!N5 -> 0 | E17: ='Star Man'!N6 -> 0 | F17: ='Star Man'!N7 -> 0 | G17: ='Star Man'!N8 -> 0 | H17: ='Star Man'!N9 -> 0 | I17: ='Star Man'!N10 -> 1 | J17: ='Star Man'!N11 -> 0 | K17: ='Star Man'!N12 -> 0 | L17: ='Star Man'!N13 -> 0 | M17: ='Star Man'!N14 -> 0 | N17: ='Star Man'!N15 -> 0 | O17: ='Star Man'!N16 -> 0 | P17: ='Star Man'!N17 -> 0 | Q17: ='Star Man'!N18 -> 0 | R17: ='Star Man'!N19 -> 0 | S17: ='Star Man'!N20 -> 0 | T17: ='Star Man'!N21 -> 1 | U17: ='Star Man'!N22 -> 0 | V17: ='Star Man'!N23 -> 0 | W17: ='Star Man'!N24 -> 0 | X17: ='Star Man'!N25 -> 0 | Y17: ='Star Man'!N26 -> 0 | Z17: ='Star Man'!N27 -> 0 | AA17: ='Star Man'!N28 -> 0 | AB17: ='Star Man'!N29 -> 0 | AC17: ='Star Man'!N30 -> 0 | AD17: ='Star Man'!N31 -> 0 | AE17: ='Star Man'!N32 -> 0 | AF17: ='Star Man'!N33 -> 0 | AG17: ='Star Man'!N34 -> 0 | AH17: ='Star Man'!N35 -> 0 | AI17: ='Star Man'!N36 -> 0 | AJ17: ='Star Man'!N37 -> 0 | AK17: ='Star Man'!N38 -> 0 | AL17: ='Star Man'!N39 -> 0 | AM17: ='Star Man'!N40 -> 0 | AN17: ='Star Man'!N41 -> 0 | AO17: ='Star Man'!N42 -> 0
B18: #VALUE! | C18: Tom Total Star Man Yellows | D18: =D17 -> 0 | E18: =D18+E17 -> 0 | F18: =E18+F17 -> 0 | G18: =F18+G17 -> 0 | H18: =G18+H17 -> 0 | I18: =H18+I17 -> 1 | J18: =I18+J17 -> 1 | K18: =J18+K17 -> 1 | L18: =K18+L17 -> 1 | ... AO18: =AN18+AO17 -> 2
B19: #VALUE! | C19: Tom Star Man Reds | D19: ='Star Man'!O5 -> 0 | E19: ='Star Man'!O6 -> 0 | F19: ='Star Man'!O7 -> 0 | G19: ='Star Man'!O8 -> 0 | H19: ='Star Man'!O9 -> 0 | I19: ='Star Man'!O10 -> 0 | J19: ='Star Man'!O11 -> 0 | K19: ='Star Man'!O12 -> 0 | L19: ='Star Man'!O13 -> 0 | M19: ='Star Man'!O14 -> 0 | N19: ='Star Man'!O15 -> 0 | O19: ='Star Man'!O16 -> 0 | P19: ='Star Man'!O17 -> 0 | Q19: ='Star Man'!O18 -> 0 | R19: ='Star Man'!O19 -> 0 | S19: ='Star Man'!O20 -> 0 | T19: ='Star Man'!O21 -> 0 | U19: ='Star Man'!O22 -> 0 | V19: ='Star Man'!O23 -> 0 | W19: ='Star Man'!O24 -> 0 | X19: ='Star Man'!O25 -> 0 | Y19: ='Star Man'!O26 -> 0 | Z19: ='Star Man'!O27 -> 0 | AA19: ='Star Man'!O28 -> 0 | AB19: ='Star Man'!O29 -> 0 | AC19: ='Star Man'!O30 -> 0 | AD19: ='Star Man'!O31 -> 0 | AE19: ='Star Man'!O32 -> 0 | AF19: ='Star Man'!O33 -> 0 | AG19: ='Star Man'!O34 -> 0 | AH19: ='Star Man'!O35 -> 0 | AI19: ='Star Man'!O36 -> 0 | AJ19: ='Star Man'!O37 -> 0 | AK19: ='Star Man'!O38 -> 0 | AL19: ='Star Man'!O39 -> 0 | AM19: ='Star Man'!O40 -> 0 | AN19: ='Star Man'!O41 -> 0 | AO19: ='Star Man'!O42 -> 0
B20: #VALUE! | C20: Tom Total Star Man Reds | D20: =D19 -> 0 | E20: =D20+E19 -> 0 | F20: =E20+F19 -> 0 | G20: =F20+G19 -> 0 | H20: =G20+H19 -> 0 | I20: =H20+I19 -> 0 | J20: =I20+J19 -> 0 | K20: =J20+K19 -> 0 | L20: =K20+L19 -> 0 | ... AO20: =AN20+AO19 -> 0
C21: GAMEWEEK | D21: GW1 | E21: GW2 | F21: GW3 | G21: GW4 | H21: GW5 | I21: GW6 | J21: GW7 | K21: GW8 | L21: GW9 | M21: GW10 | N21: GW11 | O21: GW12 | P21: GW13 | Q21: GW14 | R21: GW15 | S21: GW16 | T21: GW17 | U21: GW18 | V21: GW19 | W21: GW20 | X21: GW21 | Y21: GW22 | Z21: GW23 | AA21: GW24 | AB21: GW25 | AC21: GW26 | AD21: GW27 | AE21: GW28 | AF21: GW29 | AG21: GW30 | AH21: GW31 | AI21: GW32 | AJ21: GW33 | AK21: GW34 | AL21: GW35 | AM21: GW36 | AN21: GW37 | AO21: GW38
